<?xml version="1.0" encoding="UTF-8"?>
<testng-results skipped="0" failed="1" ignored="0" total="3" passed="2">
  <reporter-output>
  </reporter-output>
  <suite name="Suite" duration-ms="37" started-at="2020-06-24T14:34:54Z" finished-at="2020-06-24T14:34:54Z">
    <groups>
    </groups>
    <test name="Test" duration-ms="37" started-at="2020-06-24T14:34:54Z" finished-at="2020-06-24T14:34:54Z">
      <class name="com.lujiatao.jenkinstest.JenkinsTest">
        <test-method status="PASS" signature="testCase1()[pri:0, instance:com.lujiatao.jenkinstest.JenkinsTest@23ceabc1]" name="testCase1" duration-ms="10" started-at="2020-06-24T14:34:54Z" finished-at="2020-06-24T14:34:54Z">
          <reporter-output>
          </reporter-output>
        </test-method> <!-- testCase1 -->
        <test-method status="PASS" signature="testCase2()[pri:0, instance:com.lujiatao.jenkinstest.JenkinsTest@23ceabc1]" name="testCase2" duration-ms="2" started-at="2020-06-24T14:34:54Z" finished-at="2020-06-24T14:34:54Z">
          <reporter-output>
          </reporter-output>
        </test-method> <!-- testCase2 -->
        <test-method status="FAIL" signature="testCase3()[pri:0, instance:com.lujiatao.jenkinstest.JenkinsTest@23ceabc1]" name="testCase3" duration-ms="1" started-at="2020-06-24T14:34:54Z" finished-at="2020-06-24T14:34:54Z">
          <exception class="java.lang.AssertionError">
            <message>
              <![CDATA[expected [99] but found [100]]]>
            </message>
            <full-stacktrace>
              <![CDATA[java.lang.AssertionError: expected [99] but found [100]
at org.testng.Assert.fail(Assert.java:96)
at org.testng.Assert.failNotEquals(Assert.java:776)
at org.testng.Assert.assertEqualsImpl(Assert.java:137)
at org.testng.Assert.assertEquals(Assert.java:118)
at org.testng.Assert.assertEquals(Assert.java:652)
at org.testng.Assert.assertEquals(Assert.java:662)
at com.lujiatao.jenkinstest.JenkinsTest.testCase3(JenkinsTest.java:24)
at sun.reflect.NativeMethodAccessorImpl.invoke0(Native Method)
at sun.reflect.NativeMethodAccessorImpl.invoke(NativeMethodAccessorImpl.java:62)
at sun.reflect.DelegatingMethodAccessorImpl.invoke(DelegatingMethodAccessorImpl.java:43)
at java.lang.reflect.Method.invoke(Method.java:498)
at org.testng.internal.MethodInvocationHelper.invokeMethod(MethodInvocationHelper.java:124)
at org.testng.internal.Invoker.invokeMethod(Invoker.java:583)
at org.testng.internal.Invoker.invokeTestMethod(Invoker.java:719)
at org.testng.internal.Invoker.invokeTestMethods(Invoker.java:989)
at org.testng.internal.TestMethodWorker.invokeTestMethods(TestMethodWorker.java:125)
at org.testng.internal.TestMethodWorker.run(TestMethodWorker.java:109)
at org.testng.TestRunner.privateRun(TestRunner.java:648)
at org.testng.TestRunner.run(TestRunner.java:505)
at org.testng.SuiteRunner.runTest(SuiteRunner.java:455)
at org.testng.SuiteRunner.runSequentially(SuiteRunner.java:450)
at org.testng.SuiteRunner.privateRun(SuiteRunner.java:415)
at org.testng.SuiteRunner.run(SuiteRunner.java:364)
at org.testng.SuiteRunnerWorker.runSuite(SuiteRunnerWorker.java:52)
at org.testng.SuiteRunnerWorker.run(SuiteRunnerWorker.java:84)
at org.testng.TestNG.runSuitesSequentially(TestNG.java:1208)
at org.testng.TestNG.runSuitesLocally(TestNG.java:1137)
at org.testng.TestNG.runSuites(TestNG.java:1049)
at org.testng.TestNG.run(TestNG.java:1017)
at org.testng.remote.AbstractRemoteTestNG.run(AbstractRemoteTestNG.java:132)
at org.testng.remote.RemoteTestNG.initAndRun(RemoteTestNG.java:236)
at org.testng.remote.RemoteTestNG.main(RemoteTestNG.java:81)
]]>
            </full-stacktrace>
          </exception> <!-- java.lang.AssertionError -->
          <reporter-output>
          </reporter-output>
        </test-method> <!-- testCase3 -->
      </class> <!-- com.lujiatao.jenkinstest.JenkinsTest -->
    </test> <!-- Test -->
  </suite> <!-- Suite -->
</testng-results>
